Workbook
Name Slicer_Age_Group: #N/A
Name Slicer_Department: #N/A
Name Slicer_Is_Manager: #N/A
Name Slicer_Salary_Group: #N/A

Sheet Raw Data
A1: Index | B1: Employee_ID | C1: Age | D1: Department | E1: Is_Manager | F1: Join_Date | G1: Experience | H1: Salary
A2: 0 | B2: 8794 | C2: 60 | D2: Finance | E2: FALSE | F2: 24-03-94 | G2: 30 | H2: 238668
A3: 1 | B3: 8222 | C3: 28 | D3: Sales | E3: TRUE | F3: 29079 | G3: 13 | H3: 105995
A4: 2 | B4: 7643 | C4: 30 | D4: Marketing | E4: FALSE | F4: 25-09-98 | G4: 11 | H4: 96120
A5: 3 | B5: 2737 | C5: 38 | D5: HR | E5: TRUE | F5: 23-11-11 | G5: 20 | H5: 153525
A6: 4 | B6: 8557 | C6: 61 | D6: HR | E6: TRUE | F6: 27982 | G6: 31 | H6: 249192
A7: 5 | B7: 8484 | C7: 31 | D7: Marketing | E7: FALSE | F7: 30138 | G7: 14 | H7: 112443
A8: 6 | B8: 5854 | C8: 64 | D8: Finance | E8: FALSE | F8: 29931 | G8: 33 | H8: 269150
A9: 7 | B9: 6012 | C9: 33 | D9: Finance | E9: FALSE | F9: 28-09-83 | G9: 13 | H9: 99541
A10: 8 | B10: 7462 | C10: 34 | D10: Finance | E10: FALSE | F10: 22-01-21 | G10: 15 | H10: 119128
A11: 9 | B11: 7276 | C11: 23 | D11: Finance | E11: FALSE | F11: 41708 | G11: 11 | H11: 83249
A12: 10 | B12: 6621 | C12: 51 | D12: IT | E12: TRUE | F12: 27366 | G12: 26 | H12: 201259
A13: 11 | B13: 7461 | C13: 43 | D13: IT | E13: TRUE | F13: 33456 | G13: 17 | H13: 144477
A14: 12 | B14: 4181 | C14: 33 | D14: Finance | E14: TRUE | F14: 22-04-15 | G14: 18 | H14: 148126
A15: 13 | B15: 9770 | C15: 64 | D15: Marketing | E15: FALSE | F15: 30871 | G15: 29 | H15: 237357
A16: 14 | B16: 9138 | C16: 41 | D16: Finance | E16: TRUE | F16: 17-11-04 | G16: 19 | H16: 158446
A17: 15 | B17: 7182 | C17: 30 | D17: Marketing | E17: TRUE | F17: 30052 | G17: 15 | H17: 124601
A18: 16 | B18: 9901 | C18: 60 | D18: IT | E18: TRUE | F18: 22-03-01 | G18: 27 | H18: 209673
A19: 17 | B19: 9684 | C19: 25 | D19: Finance | E19: FALSE | F19: 23-11-23 | G19: 11 | H19: 88325
A20: 18 | B20: 6645 | C20: 30 | D20: Marketing | E20: FALSE | F20: 37292 | G20: 14 | H20: 117761
A21: 19 | B21: 4049 | C21: 45 | D21: IT | E21: TRUE | F21: 33857 | G21: 24 | H21: 193695
A22: 20 | B22: 7857 | C22: 56 | D22: Finance | E22: TRUE | F22: 13-05-73 | G22: 27 | H22: 223718
A23: 21 | B23: 3757 | C23: 32 | D23: Finance | E23: TRUE | F23: 31-10-09 | G23: 16 | H23: 136877
A24: 22 | B24: 9062 | C24: 49 | D24: Sales | E24: TRUE | F24: 29-07-13 | G24: 24 | H24: 201355
A25: 23 | B25: 4459 | C25: 52 | D25: HR | E25: FALSE | F25: 41979 | G25: 25 | H25: 197155
A26: 24 | B26: 2444 | C26: 43 | D26: IT | E26: TRUE | F26: 13-02-85 | G26: 22 | H26: 181254
A27: 25 | B27: 3005 | C27: 56 | D27: Sales | E27: TRUE | F27: 13-03-09 | G27: 24 | H27: 197009
A28: 26 | B28: 6797 | C28: 47 | D28: IT | E28: TRUE | F28: 20-03-96 | G28: 26 | H28: 201648
A29: 27 | B29: 5040 | C29: 37 | D29: HR | E29: TRUE | F29: 13-02-72 | G29: 22 | H29: 186028
A30: 28 | B30: 9477 | C30: 54 | D30: IT | E30: TRUE | F30: 39724 | G30: 26 | H30: 201094
A31: 29 | B31: 3555 | C31: 48 | D31: Sales | E31: TRUE | F31: 29227 | G31: 25 | H31: 192419
A32: 30 | B32: 3490 | C32: 28 | D32: IT | E32: TRUE | F32: 38026 | G32: 13 | H32: 103102
A33: 31 | B33: 3637 | C33: 62 | D33: Marketing | E33: TRUE | F33: 13-01-76 | G33: 31 | H33: 248038
A34: 32 | B34: 9629 | C34: 44 | D34: Marketing | E34: TRUE | F34: 22-07-94 | G34: 22 | H34: 178656
A35: 33 | B35: 6809 | C35: 40 | D35: IT | E35: TRUE | F35: 28011 | G35: 19 | H35: 149831
A36: 34 | B36: 8660 | C36: 34 | D36: HR | E36: TRUE | F36: 43527 | G36: 17 | H36: 137180
A37: 35 | B37: 3840 | C37: 45 | D37: Sales | E37: TRUE | F37: 15-11-72 | G37: 22 | H37: 173071
A38: 36 | B38: 8354 | C38: 45 | D38: Finance | E38: FALSE | F38: 28-09-71 | G38: 22 | H38: 177939
A39: 37 | B39: 9487 | C39: 37 | D39: Sales | E39: FALSE | F39: 45451 | G39: 14 | H39: 115812
A40: 38 | B40: 1501 | C40: 47 | D40: Marketing | E40: TRUE | F40: 17-09-88 | G40: 21 | H40: 159633
...

Sheet Cleaned Data
A1: Index | B1: Employee_ID | C1: Age | D1: Department | E1: Is_Manager | F1: Join_Date | G1: Experience | H1: Salary | I1: Age Group | J1: Salary Group
A2: 1 | B2: 8794 | C2: 60 | D2: Finance | E2: Not Manager | F2: 34417 | G2: 30 | H2: 238668 | I2: {=_xlfn.IFS(C2>50,"50+",C2>=30,"30-50",C2<30,"Under 30")} -> 50+ | J2: {=_xlfn.IFS(H2>200000,"2 Lakhs +",H2>=100000,"1-2 Lakhs",H2<100000,"Below 1 Lakhs")} -> 2 Lakhs +
A3: 2 | B3: 8222 | C3: 28 | D3: Sales | E3: Manager | F3: 29197 | G3: 13 | H3: 105995 | I3: {=_xlfn.IFS(C3>50,"50+",C3>=30,"30-50",C3<30,"Under 30")} -> Under 30 | J3: {=_xlfn.IFS(H3>200000,"2 Lakhs +",H3>=100000,"1-2 Lakhs",H3<100000,"Below 1 Lakhs")} -> 1-2 Lakhs
A4: 3 | B4: 7643 | C4: 30 | D4: Marketing | E4: Not Manager | F4: 36063 | G4: 11 | H4: 96120 | I4: {=_xlfn.IFS(C4>50,"50+",C4>=30,"30-50",C4<30,"Under 30")} -> 30-50 | J4: {=_xlfn.IFS(H4>200000,"2 Lakhs +",H4>=100000,"1-2 Lakhs",H4<100000,"Below 1 Lakhs")} -> Below 1 Lakhs
A5: 4 | B5: 2737 | C5: 38 | D5: HR | E5: Manager | F5: 40870 | G5: 20 | H5: 153525 | I5: {=_xlfn.IFS(C5>50,"50+",C5>=30,"30-50",C5<30,"Under 30")} -> 30-50 | J5: {=_xlfn.IFS(H5>200000,"2 Lakhs +",H5>=100000,"1-2 Lakhs",H5<100000,"Below 1 Lakhs")} -> 1-2 Lakhs
A6: 5 | B6: 8557 | C6: 61 | D6: HR | E6: Manager | F6: 28041 | G6: 31 | H6: 249192 | I6: {=_xlfn.IFS(C6>50,"50+",C6>=30,"30-50",C6<30,"Under 30")} -> 50+ | J6: {=_xlfn.IFS(H6>200000,"2 Lakhs +",H6>=100000,"1-2 Lakhs",H6<100000,"Below 1 Lakhs")} -> 2 Lakhs +
A7: 6 | B7: 8484 | C7: 31 | D7: Marketing | E7: Not Manager | F7: 30109 | G7: 14 | H7: 112443 | I7: {=_xlfn.IFS(C7>50,"50+",C7>=30,"30-50",C7<30,"Under 30")} -> 30-50 | J7: {=_xlfn.IFS(H7>200000,"2 Lakhs +",H7>=100000,"1-2 Lakhs",H7<100000,"Below 1 Lakhs")} -> 1-2 Lakhs
A8: 7 | B8: 5854 | C8: 64 | D8: Finance | E8: Not Manager | F8: 29902 | G8: 33 | H8: 269150 | I8: {=_xlfn.IFS(C8>50,"50+",C8>=30,"30-50",C8<30,"Under 30")} -> 50+ | J8: {=_xlfn.IFS(H8>200000,"2 Lakhs +",H8>=100000,"1-2 Lakhs",H8<100000,"Below 1 Lakhs")} -> 2 Lakhs +
A9: 8 | B9: 6012 | C9: 33 | D9: Finance | E9: Not Manager | F9: 30587 | G9: 13 | H9: 99541 | I9: {=_xlfn.IFS(C9>50,"50+",C9>=30,"30-50",C9<30,"Under 30")} -> 30-50 | J9: {=_xlfn.IFS(H9>200000,"2 Lakhs +",H9>=100000,"1-2 Lakhs",H9<100000,"Below 1 Lakhs")} -> Below 1 Lakhs
A10: 9 | B10: 7462 | C10: 34 | D10: Finance | E10: Not Manager | F10: 44218 | G10: 15 | H10: 119128 | I10: {=_xlfn.IFS(C10>50,"50+",C10>=30,"30-50",C10<30,"Under 30")} -> 30-50 | J10: {=_xlfn.IFS(H10>200000,"2 Lakhs +",H10>=100000,"1-2 Lakhs",H10<100000,"Below 1 Lakhs")} -> 1-2 Lakhs
A11: 10 | B11: 7276 | C11: 23 | D11: Finance | E11: Not Manager | F11: 41915 | G11: 11 | H11: 83249 | I11: {=_xlfn.IFS(C11>50,"50+",C11>=30,"30-50",C11<30,"Under 30")} -> Under 30 | J11: {=_xlfn.IFS(H11>200000,"2 Lakhs +",H11>=100000,"1-2 Lakhs",H11<100000,"Below 1 Lakhs")} -> Below 1 Lakhs
A12: 11 | B12: 6621 | C12: 51 | D12: IT | E12: Manager | F12: 27100 | G12: 26 | H12: 201259 | I12: {=_xlfn.IFS(C12>50,"50+",C12>=30,"30-50",C12<30,"Under 30")} -> 50+ | J12: {=_xlfn.IFS(H12>200000,"2 Lakhs +",H12>=100000,"1-2 Lakhs",H12<100000,"Below 1 Lakhs")} -> 2 Lakhs +
A13: 12 | B13: 7461 | C13: 43 | D13: IT | E13: Manager | F13: 33397 | G13: 17 | H13: 144477 | I13: {=_xlfn.IFS(C13>50,"50+",C13>=30,"30-50",C13<30,"Under 30")} -> 30-50 | J13: {=_xlfn.IFS(H13>200000,"2 Lakhs +",H13>=100000,"1-2 Lakhs",H13<100000,"Below 1 Lakhs")} -> 1-2 Lakhs
... A501: 500 | B501: 7744 | C501: 29 | D501: Finance | E501: Manager | F501: 32315 | G501: 15 | H501: 114758 | I501: {=_xlfn.IFS(C501>50,"50+",C501>=30,"30-50",C501<30,"Under 30")} -> Under 30 | J501: {=_xlfn.IFS(H501>200000,"2 Lakhs +",H501>=100000,"1-2 Lakhs",H501<100000,"Below 1 Lakhs")} -> 1-2 Lakhs

Sheet Changelog
A1: Change | B1: What was done | C1: Why
A2: Index Number | B2: Changed index from 0 to 1 numbering ,convert datatype into number | C2: Easier to Understand
A3: Age | B3: Convert datatype into number | C3: To ensure age can be correctly for calculation and analysis
A4: Join date | B4: Convert datatype into short date | C4: Enable date/year analysis
A5: Experience | B5: Convert datatype into number | C5: To enable calculation and analysis
A6: Salary | B6: Convert datatype into currency | C6: Easier to read salary values
A7: Add Age Group | B7: Added age categories | C7: Simplify age group analysis
A8: Add Salary Group | B8: Added salary category | C8: Simplify salary range analysis
A9: Check | B9: Checked for duplicate records,no duplicates were found | C9: Ensure data is unique and accurate
A10: Is Manager | B10: Convert True or False to Manager or Non-Manager | C10: To Easy to Understand

Sheet Analysis
A1: Analysis Questions | B1: Ans
A2: 1. What is the Highest Salary Of Employee? | B2: =MAX('Cleaned Data'!H2:H501) -> 293410
A3: 2. How many Employees are from the HR Department and are Manager? | B3: =COUNTIFS('Cleaned Data'!D2:D501,'Cleaned Data'!D484,'Cleaned Data'!E2:E501,'Cleaned Data'!E3) -> 46
A4: 3. What is the Average Work Experience of the Employees? | B4: =AVERAGE('Cleaned Data'!G2:G501) -> 21.316
A5: 4. What is the Average Salary of Employees? | B5: =AVERAGE('Cleaned Data'!H2:H501) -> 170634.37

Sheet Insights
A2: Questions
A3: 1. Which Department has the Highest Number of Employees?
A4: 2. How many Employees are Managers and Non-Mangers?
A5: 3. What is the Average Salary of Each Department?
A6: 4. How many Employees is are there in each Age Group?
A7: 5. How many Employees is are there in each Salary Range?
A9: Analysis Questions
A10: 1. What is the Highest Salary Of Employee?
A11: 2. How many Employees are from the HR Department and are Manager?
A12: 3. What is the Average Work Experience of the Employees?
A13: 4. What is the Average Salary of Employees?

Sheet Charts
A3: Row Labels | B3: Count of Index
A4: Finance | B4: 57
A5: HR | B5: 41
A6: IT | B6: 51 | N6: =GETPIVOTDATA("Index",$A$3) -> 243
A7: Marketing | B7: 48
A8: Sales | B8: 46
A9: Grand Total | B9: 243
A24: Row Labels | B24: Count of Index
A25: Not Manager | B25: 243
A26: Grand Total | B26: 243
A32: C | B32: Average of Salary
A33: Finance | B33: 165951.91
A34: HR | B34: 169498.46
A35: IT | B35: 172284.29
A36: Marketing | B36: 177039.19
A37: Sales | B37: 162194.85
A38: Grand Total | B38: 169358.19
B43: Column Labels
B44: 30-50 | C44: 50+ | D44: Under 30 | E44: Grand Total
A45: Count of Index | B45: 123 | C45: 81 | D45: 39 | E45: 243
B60: Column Labels
B61: 1-2 Lakhs | C61: 2 Lakhs + | D61: Below 1 Lakhs | E61: Grand Total
A62: Count of Index | B62: 136 | C62: 78 | D62: 29 | E62: 243
A73: =COUNT('Cleaned Data'!A2:A501) -> 500
A80: C | B80: Sum of Salary
A81: Finance | B81: 9459259
A82: HR | B82: 6949437
A83: IT | B83: 8786499 | D83: =GETPIVOTDATA("Salary",$A$80) -> 41154039
A84: Marketing | B84: 8497881
A85: Sales | B85: 7460963
A86: Grand Total | B86: 41154039
A91: C | B91: Average of Experience
A92: Finance | B92: 20.736842
A93: HR | B93: 21
A94: IT | B94: 21.568627
A95: Marketing | B95: 22.125
A96: Sales | B96: 20.326087
A97: Grand Total | B97: 21.152263

Sheet Dashboard
A1: EMPLOYEES DATA DASHBOARD

Sheet Findings and Recommendation
B3: FINDINGS | C3: RECOMMENDATION
B4: IT has the highest number of employees, while HR and Marketing have fewer employees. | C4: Review staffing levels and provide additional employees to departments if needed.
B5: The number of managers and non-managers is slightly different. | C5: Review the manager-to-employee ratio to maintain an effective management structure.
B6: Marketing has the highest number of employees, while Sales have fewer employees. | C6: increase sales staffing to improve sales performance and balance the workforce.
B7: The 30–50 age group has the highest number of employees (265), while the under 30 age group has the lowest (77). | C7: Provide suitable training and career development opportunities based on the workforce age distribution.
B8: The ₹1–2 Lakh salary range has the highest number of employees (297), while Below ₹1 Lakh has the lowest (48). | C8: Review salary distribution based on employees roles and experience.
